<?xml version="1.0"?>
<robot xmlns:xacro="http://www.ros.org/wiki/xacro"  name="robot">

    <xacro:include filename="inertial_macros.xacro" />

    <material name="white">
        <color rgba="1 1 1 1" />
    </material>

    <material name="orange">
        <color rgba="1 0.5 0 1" />
    </material>
    
    <material name="blue">
        <color rgba="0 0 1 1" />
    </material>

    <material name="black">
        <color rgba="0 0 0 1" />
    </material>


    <!-- CHASIS-BASE_LINK JOINT -->

    <joint name="chasis_joinnt" type="fixed">
        <parent link="base_link" />
        <child link="chasis" />
        <origin xyz="-0.1 0 0" rpy="0 0 0" />
    </joint>

    <!-- CHASIS LINK -->

    <link name="chasis">
        <visual>
            <origin xyz="0.15 0 0.075" rpy="0 0 0" />
            <geometry>
                <box size="0.3 0.3 0.15" />
            </geometry>
            <material name="white" />
        </visual>

        <collision>
            <origin xyz="0.15 0 0.075" rpy="0 0 0" />
            <geometry>
                <box size="0.3 0.3 0.15" />
            </geometry>
        </collision>

        <xacro:inertial_box mass="5" x="0.3" y="0.3" z="0.15" >
            <origin  xyz="0.15 0 0.075"  rpy="0 0 0"/>
        </xacro:inertial_box>
    </link>

    <!-- LEFT WHEEL JOINT -->
     <joint name="left_wheel_joint" type="continuous">
        <parent link="base_link" />
        <child link="left_wheel_link" />
        <origin xyz="0 0.175 0" rpy="-${pi/2} 0 0"/>
        <axis xyz="0 0 1" />
     </joint>

    <!-- LFT_WHEEL LINK  -->
     <link name="left_wheel_link">
        <visual>
            <geometry>
                <cylinder radius="0.05" length="0.04" />
            </geometry>
            <material name="blue"/>
        </visual>

        <collision>
            <geometry>
                <cylinder radius="0.05" length="0.04" />
            </geometry>
        </collision>

        <xacro:inertial_cylinder mass="0.1" length="0.04" radius="0.05">
            <origin xyz="0 0 0" rpy="0 0 0"/>
        </xacro:inertial_cylinder>
     </link>

         <!-- RIGHT WHEEL JOINT -->
     <joint name="right_wheel_joint" type="continuous">
        <parent link="base_link" />
        <child link="right_wheel_link" />
        <origin xyz="0 -0.175 0" rpy="${pi/2} 0 0"/>
        <axis xyz="0 0 -1" />
     </joint>

    <!-- RIGHT_WHEEL LINK  -->
     <link name="right_wheel_link">
        <visual>
            <geometry>
                <cylinder radius="0.05" length="0.04" />
            </geometry>
            <material name="blue"/>
        </visual>

        <collision>
            <geometry>
                <cylinder radius="0.05" length="0.04" />
            </geometry>
        </collision>

        <xacro:inertial_cylinder mass="0.1" length="0.04" radius="0.05">
            <origin xyz="0 0 0" rpy="0 0 0"/>
        </xacro:inertial_cylinder>
     </link>

     <!-- CASTER WHEEL JOINT -->
      <joint name="caster_wheel_joint" type="fixed">
        <parent link="chasis" />
        <child link="caster_link" />
        <origin xyz="0.24 0 0" rpy="0 0 0" />

      </joint>

      <!-- CASTER WHEEL LINK -->
       <link name="caster_link">
        <visual>
            <origin xyz="0 0 0" rpy="0 0 0" />
            <geometry>
                <sphere radius="0.05" />
            </geometry>
            <material name="black" />
        </visual>

        <collision>
            <origin xyz="0 0 0" rpy="0 0 0" />
            <geometry>
                <sphere radius="0.05" />
            </geometry>
        </collision>
        <xacro:inertial_sphere mass="0.1" radius="0.05">
            <origin xyz="0 0 0" rpy="0 0 0"/>
        </xacro:inertial_sphere>
       </link>

</robot>